/*
Using try and catch block JS doesn't stop although it found error.
*/
// try{
//     console.log(a + b);         //This error generate from JS by default.
// }catch(err){                    //catch accept err object
//     console.log(err);
//     console.log("There was a Reference Error.");
// }
// console.log("My program doesn't stop.")

// try{
//     throw new ReferenceError();    //This error generated by me.
// }catch(err){
//     console.log(err);              //Output err object
//     console.log("There was a Reference Error.");
// }
// console.log("My program doesn't stop.")

console.log("Converting to base 2: ", (10).toString(2));
console.log("Converting to base 8: ", (10).toString(8))